Workbook
Name Bueno: 'Datos Generales'!$I$30:$J$30
Name Malo: 'Datos Generales'!$J$30
Name Operativo_y_estéticamente_aceptable._Presenta_marcas_superficiales_mínimas_propias_del_uso_reciente__pero_no_afectan_la_apariencia_general_ni_la_seguridad.: 'Datos Generales'!$I$30:$J$30
Name Regular: 'Datos Generales'!$I$30

Sheet Instrucciones
A1: Levantamiento de Datos del Edificio de Aulas — Guía de uso
A3: Este libro está diseñado para levantar, de forma detallada, la información física, de mobiliario, de uso y de accesibilidad/seguridad de un edificio de aulas de 5 pisos. Cada hoja cubre un aspecto distinto del levantamiento y agrupa sus columnas en categorías para facilitar la lectura. Complete una hoja a la vez, recorriendo el edificio piso por piso y espacio por espacio.
A5: Contenido del libro
A6: • Datos Generales: Ficha única con la información global del edificio, organizada en categorías (1, 2, 3...) y subcategorías (1.1, 1.2...): identificación, datos constructivos, servicios, accesos/seguridad general y exteriores.
A7: • Inventario de Espacios: Un registro por cada salón/espacio del edificio: piso, Categoría y Subcategoría del espacio, área, capacidad, estado y condiciones de acceso.
A8: • Mobiliario y Equipo: El detalle de cada espacio: cuántas sillas, mesas, pizarras, luminarias, tomacorrientes, equipos, aires acondicionados, etc. hay y en qué estado.
A9: • Horarios de Uso: Registro de en qué días, horas y para qué se usa cada espacio (una fila por sesión/franja horaria observada o programada).
A10: • Accesibilidad y Seguridad: Condiciones de accesibilidad (rampas, anchos de puerta, ascensores) y de seguridad (extintores, alarmas, rutas de evacuación) por espacio.
A11: • Instalaciones por Piso: Datos por piso que no son de un solo salón: baños, tableros eléctricos, bebederos, estado de acabados.
A12: • Resumen: Tablero con totales y cruces calculados automáticamente a partir de las demás hojas (no se llena a mano).
A14: Categorías y subcategorías
A15: Encabezados agrupados: en cada hoja de datos, la fila azul oscuro (justo encima del encabezado de columna) agrupa las columnas relacionadas bajo una categoría, por ejemplo 'Mobiliario', 'Tecnología y Enseñanza' o 'Seguridad y Emergencia'.
... A31: • Celdas en blanco: Celdas listas para que usted digite o seleccione la información.

Sheet Resumen
A2: Esta hoja se calcula automáticamente a partir de las demás hojas — no escriba aquí. Mientras la fila de EJEMPLO siga presente en las otras hojas, los totales la incluyen; bórrela (Suprimir, sin eliminar la fila) cuando inicie el levantamiento real para que los totales reflejen solo datos reales.
A4: 1. Totales Generales
A5: Total de espacios inventariados | B5: =COUNTA('Inventario Espacios'!$B$5:$B$74) -> 0
A6: Total de sillas registradas | B6: =SUM('Mobiliario y Equipo'!$C$5:$C$75) -> 40
A7: Total de luminarias registradas | B7: =SUM('Mobiliario y Equipo'!$M$5:$M$75) -> 8
A8: Luminarias funcionando | B8: =SUM('Mobiliario y Equipo'!$N$5:$N$75) -> 7
A9: % de luminarias funcionando | B9: =IFERROR(B8/B7,"") -> 0.875
A10: Total de sesiones de uso registradas (Horarios) | B10: =COUNTA('Horarios de Uso'!$B$5:$B$155) -> 1
A11: Espacios con acceso libre | B11: =COUNTIFS('Inventario Espacios'!$T$5:$T$74,"Sí") -> 0
A12: % de espacios con acceso libre | B12: =IFERROR(B11/B5,"")
A13: Espacios en buen estado | B13: =COUNTIFS('Inventario Espacios'!#REF!,"Bueno") -> #REF!
A14: Espacios en estado regular | B14: =COUNTIFS('Inventario Espacios'!#REF!,"Regular") -> #REF!
A15: Espacios en mal estado | B15: =COUNTIFS('Inventario Espacios'!#REF!,"Malo") -> #REF!
A16: Total de sanitarios en el edificio | B16: =SUM('Instalaciones por Piso'!#REF!) -> #REF!
A17: Total de extintores registrados (por piso) | B17: =SUM('Instalaciones por Piso'!#REF!) -> #REF!
A19: 2. Espacios y Sillas por Piso
A20: Piso | B20: N.º de espacios | C20: N.º de sillas
A21: 1 | B21: =COUNTIFS('Inventario Espacios'!$A$5:$A$74,$A21) -> 0 | C21: =SUMIFS('Mobiliario y Equipo'!$C$5:$C$75,'Mobiliario y Equipo'!$A$5:$A$75,$A21) -> 40
A22: 2 | B22: =COUNTIFS('Inventario Espacios'!$A$5:$A$74,$A22) -> 0 | C22: =SUMIFS('Mobiliario y Equipo'!$C$5:$C$75,'Mobiliario y Equipo'!$A$5:$A$75,$A22) -> 0
A23: 3 | B23: =COUNTIFS('Inventario Espacios'!$A$5:$A$74,$A23) -> 0 | C23: =SUMIFS('Mobiliario y Equipo'!$C$5:$C$75,'Mobiliario y Equipo'!$A$5:$A$75,$A23) -> 0
A24: 4 | B24: =COUNTIFS('Inventario Espacios'!$A$5:$A$74,$A24) -> 0 | C24: =SUMIFS('Mobiliario y Equipo'!$C$5:$C$75,'Mobiliario y Equipo'!$A$5:$A$75,$A24) -> 0
A25: 5 | B25: =COUNTIFS('Inventario Espacios'!$A$5:$A$74,$A25) -> 0 | C25: =SUMIFS('Mobiliario y Equipo'!$C$5:$C$75,'Mobiliario y Equipo'!$A$5:$A$75,$A25) -> 0
A27: 3. Espacios por Categoría
A28: Categoría del espacio | B28: N.º de espacios
A29: Académico | B29: =COUNTIFS('Inventario Espacios'!$C$5:$C$74,$A29) -> 0
A30: Administrativo | B30: =COUNTIFS('Inventario Espacios'!$C$5:$C$74,$A30) -> 0
A31: Bienestar y Servicios | B31: =COUNTIFS('Inventario Espacios'!$C$5:$C$74,$A31) -> 0
A32: Circulación | B32: =COUNTIFS('Inventario Espacios'!$C$5:$C$74,$A32) -> 0
A33: Almacenamiento | B33: =COUNTIFS('Inventario Espacios'!$C$5:$C$74,$A33) -> 0
A34: Otro | B34: =COUNTIFS('Inventario Espacios'!$C$5:$C$74,$A34) -> 0
A36: 4. Espacios por Subcategoría
A37: Subcategoría del espacio | B37: N.º de espacios
A38: Aula | B38: =COUNTIFS('Inventario Espacios'!$D$5:$D$74,$A38) -> 0
A39: Laboratorio | B39: =COUNTIFS('Inventario Espacios'!$D$5:$D$74,$A39) -> 0
A40: Auditorio | B40: =COUNTIFS('Inventario Espacios'!$D$5:$D$74,$A40) -> 0
A41: Biblioteca | B41: =COUNTIFS('Inventario Espacios'!$D$5:$D$74,$A41) -> 0
A42: Oficina | B42: =COUNTIFS('Inventario Espacios'!$D$5:$D$74,$A42) -> 0
A43: Sala de profesores | B43: =COUNTIFS('Inventario Espacios'!$D$5:$D$74,$A43) -> 0
A44: Sala de reuniones | B44: =COUNTIFS('Inventario Espacios'!$D$5:$D$74,$A44) -> 0
A45: Baño | B45: =COUNTIFS('Inventario Espacios'!$D$5:$D$74,$A45) -> 0
...

Sheet Datos Generales
A1: Datos Generales del Edificio
A2: Complete una sola vez la información global del edificio, organizada por categorías y subcategorías. Las celdas de la columna 'Valor' son para llenar; algunas tienen lista desplegable.
A4: Campo | B4: Valor | C4: Notas / Observaciones
A5: 1. Identificación del Edificio
A6: 1.1 Ubicación y Datos Básicos
A7: Nombre del edificio
A8: Código / identificador interno
A9: Institución / campus
A10: Dirección
A11: Ciudad
A12: Coordenadas GPS (lat, long)
A13: Uso principal del edificio
A14: 1.2 Levantamiento
A15: Año de construcción
A16: Fecha del levantamiento
... A27: Año de última remodelación
A28: Estado general de la estructura | H28: Estado
A29: Material predominante de fachada | H29: Bueno | I29: Regular | J29: Malo
A30: 2.2 Circulación Vertical | H30: Operativo y estéticamente aceptable. Presenta marcas superficiales mínimas propias del uso reciente, pero no afectan la apariencia general ni la seguridad. | I30: Desgaste evidente por el paso del tiempo o alto tráfico (pintura opaca, rayones visibles, decoloración, tapicería desgastada). Sigue siendo seguro y funcional, pero requerirá mantenimiento | J30: Falla severa que impide el uso del elemento o representa un riesgo de seguridad. Ejemplos: mobiliario roto, vidrios fracturados, cables eléctricos expuestos, filtración de agua activa, puerta trabada o colapso de cielo raso. Requiere intervención inmediata.
A31: Número de escaleras
A32: Ancho promedio de escaleras (m)
A33: Material de las escaleras
A34: Estado de las escaleras
A35: Número de ascensores
A36: Capacidad del ascensor (kg / personas)
A37: Estado de los ascensores
A38: ¿Tiene rampas de acceso?
A39: Número de rampas
A40: 3. Servicios e Instalaciones Generales
A41: 3.1 Energía y Agua
A42: Empresa de suministro eléctrico
... A81: Accesibilidad exterior (andenes, rampas de ingreso)

Sheet Inventario Espacios
A1: Inventario de Espacios
A2: Una fila por cada salón u otro espacio del edificio (aulas, laboratorios, oficinas, baños, depósitos, etc.). Clasifique cada espacio con Categoría y Subcategoría, y use el mismo 'Código de espacio' en las demás hojas para poder cruzar la información.
A3: Identificación | C3: Clasificación del Espacio | T3: Acceso | Y3: Estado | Z3: Registro
A4: Piso | B4: Código de espacio | C4: Categoría del espacio | D4: Subcategoría del espacio | E4: Uso actual | F4: Área aprox. (m²) | G4: Altura de techo (m) | H4: Capacidad observada (sillas contadas) | I4: Capacidad observada (sillas docente) | J4: Puertas | M4: Ventanas | P4: Muros | S4: Orientación Espacio | T4: ¿Acceso libre? | U4: Tipo de control de acceso | V4: Responsable de acceso / llave | W4: Patologías | Y4: Estado general | Z4: Observaciones | AA4: Fecha de registro
J5: N.º de puertas | K5: Estado puerta | L5: Observación | M5: N.º de ventanas | N5: Estado Ventanas | O5: Observación | P5: Acabado | Q5: Estado | R5: Observación | W5: Tipo | X5: Ubicación

Sheet Mobiliario y Equipo
A1: Mobiliario y Equipo
A2: El detalle de mobiliario, iluminación y equipo de cada espacio registrado en 'Inventario de Espacios'. Use el mismo Piso y Código de espacio para poder cruzar los datos entre hojas.
A3: Identificación | C3: Mobiliario | G3: Tecnología y Enseñanza | L3: Instalaciones Eléctricas e Iluminación | Q3: Otros Equipos | S3: Registro
A4: Piso | B4: Código de espacio | C4: N.º de sillas | D4: Sillas en buen estado | E4: N.º de pupitres | F4: Escritorio docente | G4: N.º de tablero | H4: Tipo de tablero | I4: N.º de proyectores / video beam | J4: Pantalla inteligente | K4: N.º de computadores / equipos | L4: N.º de tomacorrientes | M4: N.º de luminarias | N4: Luminarias funcionando | O4: Tipo de iluminación | P4: Cortinas / persianas | Q4: Sistema de audio / altavoces | R4: Extintor en el espacio | S4: Observaciones
A5: 1 | B5: 101 | C5: 40 | D5: 37 | E5: 20 | F5: Sí | G5: 1 | H5: Acrílico | I5: 1 | J5: Sí | K5: 1 | L5: 12 | M5: 8 | N5: 7 | O5: LED | P5: Sí | Q5: No | R5: Sí | S5: 2 sillas con espaldar roto

Sheet Horarios de Uso
A1: Horarios de Uso
A2: Una fila por cada franja horaria en que un espacio está en uso (clase, evento, reunión, mantenimiento, etc.). Registre una fila por cada día y horario distinto en que observe o programe actividad en el espacio.
A3: Identificación | C3: Fecha y Horario | I3: Actividad | M3: Registro
A4: Piso | B4: Código de espacio | C4: Horas | D4: Lunes | E4: Martes | F4: Miércoles | G4: Jueves | H4: Viernes | I4: Materia / Actividad / Evento | J4: Docente / Responsable | K4: N.º de usuarios / estudiantes | L4: Tipo de uso | M4: Observaciones
A5: 1 | B5: A-101 | C5: 6 - 7 | I5: Cálculo Diferencial | J5: Prof. Ana Rodríguez | K5: 35 | L5: Clase regular | M5: Grupo A - primer semestre
C6: 7 - 8 | D6: Fitomejoramiento (Ingenieria Agronomica) | E6: Cálculo III (Ingenieria civil)
C7: 8 - 9
C8: 9 - 10
C9: 10 - 11 | D9: Clase
C10: 11 - 12
C11: 12 - 13
C12: 13 - 14
C13: 14 - 15
C14: 15 - 16
C15: 16 - 17 | D15: Didáctica Cuerpo y Corporeidad (Licenciatura en educación infantil)
C16: 17 - 18
C17: 18 - 19 | D17: Proyecto Pedagógico Investigativo IV (Licenciatura en educación infantil)
C18: 19 - 20
C19: 20 - 21
C20: 21 - 22
C21: 22 - 23

Sheet Accesibilidad y Seguridad
A1: Accesibilidad y Seguridad
A2: Condiciones de accesibilidad universal y de seguridad/emergencia de cada espacio registrado en 'Inventario de Espacios'.
A3: Identificación | C3: Accesibilidad | J3: Seguridad y Emergencia | R3: Registro
A4: Piso | B4: Código de espacio | C4: Acceso para silla de ruedas | D4: Ancho de puerta (cm) | E4: Rampa de acceso cercana | F4: Ascensor accesible a este piso | G4: Baño accesible cercano | H4: Señalización braille | I4: Piso podotáctil | J4: Extintor cercano | K4: Detector de humo | L4: Red rociadores | M4: Alarma contra incendios audible | N4: Ruta de evacuación señalizada | O4: Salida de emergencia cercana | P4: Iluminación de emergencia | Q4: Equipo de primeros auxilios cercano | R4: Observaciones
A5: 1 | B5: 101 | C5: Sí | D5: 95 | E5: Sí | F5: Sí | G5: Sí | H5: No | I5: No | J5: Sí | K5: Sí | M5: Sí | N5: Sí | O5: Sí | P5: Sí | Q5: Sí | R5: Puerta cumple ancho mínimo; falta señalización braille

Sheet Instalaciones por Piso
A1: Instalaciones por Piso
A2: Una fila por cada piso del edificio (1 a 5), con información que no corresponde a un solo salón: baños, tableros eléctricos, bebederos y estado general de acabados. La columna Piso ya viene diligenciada.
A3: Identificación | B3: Servicios Sanitarios | F3: Instalaciones Eléctricas | I3: Estado de Acabados | O3: Registro
A4: Piso | B4: Baños | C4: Cantidad | D4: Baños accesibles | E4: N.º de lavamanos | F4: Tablero eléctrico en el piso | G4: Ubicación del tablero eléctrico | H4: Depósitos / bodegas en el piso | I4: Estado de pisos | J4: Estado de muros | K4: Estado de cielo raso | L4: Filtraciones de agua visibles | M4: Ubicación de filtraciones | N4: Ventilación natural | O4: Observaciones general acabados
A5: 1 | B5: Hombres | H5: 1 | I5: Bueno | J5: Regular | K5: Bueno | L5: No | O5: Pasillo principal con buena iluminación natural
B6: Mujeres
A7: 2 | B7: Hombres | H7: 2 | I7: Bueno | J7: Regular | K7: Bueno | L7: No | O7: Pasillo principal con buena iluminación natural
B8: Mujeres
A9: 3 | B9: Hombres | H9: 3 | I9: Bueno | J9: Regular | K9: Bueno | L9: No | O9: Pasillo principal con buena iluminación natural
B10: Mujeres
A11: 4 | B11: Hombres | H11: 4 | I11: Bueno | J11: Regular | K11: Bueno | L11: No | O11: Pasillo principal con buena iluminación natural
B12: Mujeres
A13: 5 | B13: Hombres | H13: 5 | I13: Bueno | J13: Regular | K13: Bueno | L13: No | O13: Pasillo principal con buena iluminación natural
B14: Mujeres

Sheet Listas
A1: Sí/No | B1: Sí/No/Parcial | C1: Sí/No/No aplica | D1: Estado | E1: Piso | F1: Tipo de espacio (ref.) | G1: Forma | H1: Orientación | I1: Tipo de acceso | J1: Tipo de tablero | K1: Tipo de iluminación | L1: Día de la semana | M1: Tipo de uso | N1: Sistema estructural | O1: Control de acceso general | P1: Categoría del espacio | Q1: Subcategoría del espacio | R1: Patologías
A2: Sí | B2: Sí | C2: Sí | D2: Bueno | E2: 1 | F2: Aula | G2: Rectangular | H2: Norte | I2: Libre | J2: Acrílico blanco | K2: LED | L2: Lunes | M2: Clase regular | N2: Concreto | O2: Libre | P2: Académico | Q2: Aula | R2: Humedad de obra
A3: No | B3: No | C3: No | D3: Regular | E3: 2 | F3: Laboratorio | G3: Cuadrado | H3: Sur | I3: Llave | J3: Acrílico movible | K3: Fluorescente | L3: Martes | M3: Laboratorio | N3: Acero | O3: Portería | P3: Administrativo | Q3: Laboratorio | R3: Humedad capilar
B4: Parcial | D4: Malo | E4: 3 | F4: Auditorio | G4: Irregular | H4: Este | I4: Tarjeta | J4: Vidrio templado | K4: Incandescente | L4: Miércoles | M4: Evento especial | N4: Mampostería | O4: Tarjeta | P4: Bienestar y Servicios | Q4: Auditorio | R4: Humedad por filtración
E5: 4 | F5: Oficina | H5: Oeste | I5: Solicitud previa | J5: Ninguna | K5: Mixta | L5: Jueves | M5: Reunión | N5: Mixto | O5: Biométrico | P5: Circulación | Q5: Biblioteca | R5: Humedad por condensación
E6: 5 | F6: Sala de profesores | H6: Norte-Sur | I6: Portería | L6: Viernes | M6: Mantenimiento | N6: Otro | O6: Mixto | P6: Almacenamiento | Q6: Oficina | R6: Humedad accidental
F7: Depósito/Bodega | H7: Este-Oeste | L7: Sábado | M7: Otro | P7: Otro | Q7: Sala de profesores | R7: Suciedad por deposito
F8: Cafetería | L8: Domingo | Q8: Sala de reuniones | R8: Suciedad por lavado diferencial
F9: Biblioteca | Q9: Cafetería | R9: Erosión atmosférica
F10: Sala de reuniones | Q10: Enfermería/Primeros auxilios | R10: Grietas por carga
F11: Pasillo/Circulación | Q11: Pasillo | R11: Grietas por dilatación y contracción
F12: Otro | Q12: Escalera | R12: Fisuras por soporte
Q13: Ascensor | R13: Fisuras por acabado
Q14: Vestíbulo/Hall | R14: Desprendimiento de acabo continuo
Q15: Depósito/Bodega | R15: Despremiento de acabado por elementos
Q16: Archivo | R16: Erosión mecánica
Q17: Otro | R17: Organismos animales
R18: Organismos vegetales
R19: Eflorescencias
